Workbook

Sheet Corrected Targets
A1: id | B1: hf_code | C1: hf_name | F1: HF Match | G1: Pop Match | H1: Region | I1: province_code | J1: province_iso_code | K1: province | L1: district_code | M1: district_iso_code | N1: district | O1: churchtype | P1: is_church | Q1: status | R1: hf_type | S1: province_id | T1: total_pop | U1: pop_15_44_yrs | V1: pop_less_then_1_yr | W1: estimated_births | X1: preg_target | Y1: non_preg_target
A2: 78 | B2: 30301 | C2: Agevairu SC | D2: Agevairu SC | E2: 10532 | F2: =IF(C2=D2,"Match","Not Match") -> Match | G2: =IF(E2=T2,"Match","Not Match") -> Match | H2: Southern | I2: 3 | J2: PG-CPM | K2: Central | L2: 303 | M2: PG0303 | N2: KAIRUKU/HIRI | P2: FALSE | Q2: Active | R2: HF | S2: 3 | T2: 10532 | U2: =T2*20% -> 2106.4 | V2: 269 | W2: 207 | X2: =T2*3% -> 315.96 | Y2: =U2-X2 -> 1790.44
A3: 79 | B3: 30302 | C3: Akufa SC | D3: Akufa SC | E3: 6227 | F3: =IF(C3=D3,"Match","Not Match") -> Match | G3: =IF(E3=T3,"Match","Not Match") -> Match | H3: Southern | I3: 3 | J3: PG-CPM | K3: Central | L3: 303 | M3: PG0303 | N3: KAIRUKU/HIRI | O3: Catholic | P3: TRUE | Q3: Active | R3: HF | S3: 3 | T3: 6227 | U3: =T3*20% -> 1245.4 | V3: 169 | W3: 130 | X3: =T3*3% -> 186.81 | Y3: =U3-X3 -> 1058.59
A4: 80 | B4: 30303 | C4: Bakoiudu SC | D4: Bakoiudu SC | E4: 3690 | F4: =IF(C4=D4,"Match","Not Match") -> Match | G4: =IF(E4=T4,"Match","Not Match") -> Match | H4: Southern | I4: 3 | J4: PG-CPM | K4: Central | L4: 303 | M4: PG0303 | N4: KAIRUKU/HIRI | O4: Catholic | P4: TRUE | Q4: Active | R4: HF | S4: 3 | T4: 3690 | U4: =T4*20% -> 738 | V4: 104 | W4: 80 | X4: =T4*3% -> 110.7 | Y4: =U4-X4 -> 627.3
A5: 11392 | B5: 30107 | C5: Bam CHP | D5: Bam CHP | E5: 5038 | F5: =IF(C5=D5,"Match","Not Match") -> Match | G5: =IF(E5=T5,"Match","Not Match") -> Match | H5: Southern | I5: 3 | J5: PG-CPM | K5: Central | L5: 301 | M5: PG0301 | N5: ABAU | P5: FALSE | Q5: Active | R5: HF | S5: 3 | T5: 5038 | U5: =T5*20% -> 1007.6 | V5: 547 | W5: 418 | X5: =T5*3% -> 151.14 | Y5: =U5-X5 -> 856.46
A6: 81 | B6: 30304 | C6: Bereina HC | D6: Bereina HC | E6: 14298 | F6: =IF(C6=D6,"Match","Not Match") -> Match | G6: =IF(E6=T6,"Match","Not Match") -> Match | H6: Southern | I6: 3 | J6: PG-CPM | K6: Central | L6: 303 | M6: PG0303 | N6: KAIRUKU/HIRI | P6: FALSE | Q6: Active | R6: HF | S6: 3 | T6: 14298 | U6: =T6*20% -> 2859.6 | V6: 345 | W6: 312 | X6: =T6*3% -> 428.94 | Y6: =U6-X6 -> 2430.66
A7: 97 | B7: 30401 | C7: Boku SC | D7: Boku SC | E7: 3726 | F7: =IF(C7=D7,"Match","Not Match") -> Match | G7: =IF(E7=T7,"Match","Not Match") -> Match | H7: Southern | I7: 3 | J7: PG-CPM | K7: Central | L7: 304 | M7: PG0304 | N7: RIGO | P7: FALSE | Q7: Active | R7: HF | S7: 3 | T7: 3726 | U7: =T7*20% -> 745.2 | V7: 278 | W7: 252 | X7: =T7*3% -> 111.78 | Y7: =U7-X7 -> 633.42
A8: 102 | B8: 30406 | C8: Boregaina SC | D8: Boregaina SC | E8: 4954 | F8: =IF(C8=D8,"Match","Not Match") -> Match | G8: =IF(E8=T8,"Match","Not Match") -> Match | H8: Southern | I8: 3 | J8: PG-CPM | K8: Central | L8: 304 | M8: PG0304 | N8: RIGO | O8: Salvation Army | P8: TRUE | Q8: Active | R8: HF | S8: 3 | T8: 4954 | U8: =T8*20% -> 990.8 | V8: 228 | W8: 207 | X8: =T8*3% -> 148.62 | Y8: =U8-X8 -> 842.18
A9: 65 | B9: 30101 | C9: Boru HC | D9: Boru HC | E9: 1997 | F9: =IF(C9=D9,"Match","Not Match") -> Match | G9: =IF(E9=T9,"Match","Not Match") -> Match | H9: Southern | I9: 3 | J9: PG-CPM | K9: Central | L9: 301 | M9: PG0301 | N9: ABAU | O9: United Church | P9: TRUE | Q9: Active | R9: HF | S9: 3 | T9: 1997 | U9: =T9*20% -> 399.4 | V9: 136 | W9: 123 | X9: =T9*3% -> 59.91 | Y9: =U9-X9 -> 339.49
A10: 90 | B10: 30313 | C10: Doa SC | D10: Doa SC | E10: 4111 | F10: =IF(C10=D10,"Match","Not Match") -> Match | G10: =IF(E10=T10,"Match","Not Match") -> Match | H10: Southern | I10: 3 | J10: PG-CPM | K10: Central | L10: 303 | M10: PG0303 | N10: KAIRUKU/HIRI | P10: FALSE | Q10: Active | R10: HF | S10: 3 | T10: 4111 | U10: =T10*20% -> 822.2 | V10: 342 | W10: 315 | X10: =T10*3% -> 123.33 | Y10: =U10-X10 -> 698.87
A11: 98 | B11: 30402 | C11: Dorobisoro SC | D11: Dorobisoro SC | E11: 2310 | F11: =IF(C11=D11,"Match","Not Match") -> Match | G11: =IF(E11=T11,"Match","Not Match") -> Match | H11: Southern | I11: 3 | J11: PG-CPM | K11: Central | L11: 304 | M11: PG0304 | N11: RIGO | P11: FALSE | Q11: Active | R11: HF | S11: 3 | T11: 2310 | U11: =T11*20% -> 462 | V11: 243 | W11: 224 | X11: =T11*3% -> 69.3 | Y11: =U11-X11 -> 392.7
A12: 82 | B12: 30305 | C12: Efogi SC | D12: Efogi SC | E12: 1202 | F12: =IF(C12=D12,"Match","Not Match") -> Match | G12: =IF(E12=T12,"Match","Not Match") -> Match | H12: Southern | I12: 3 | J12: PG-CPM | K12: Central | L12: 303 | M12: PG0303 | N12: KAIRUKU/HIRI | O12: Seventh-Day Adventist | P12: TRUE | Q12: Active | R12: HF | S12: 3 | T12: 1202 | U12: =T12*20% -> 240.4 | V12: 210 | W12: 193 | X12: =T12*3% -> 36.06 | Y12: =U12-X12 -> 204.34
A13: 70 | B13: 30201 | C13: Fane SC | D13: Fane SC | E13: 10766 | F13: =IF(C13=D13,"Match","Not Match") -> Match | G13: =IF(E13=T13,"Match","Not Match") -> Match | H13: Southern | I13: 3 | J13: PG-CPM | K13: Central | L13: 302 | M13: PG0302 | N13: GOILALA | O13: Catholic | P13: TRUE | Q13: Active | R13: HF | S13: 3 | T13: 10766 | U13: =T13*20% -> 2153.2 | V13: 1478 | W13: 1181 | X13: =T13*3% -> 322.98 | Y13: =U13-X13 -> 1830.22
A14: 83 | B14: 30306 | C14: Goldie SC | D14: Goldie SC | E14: 1854 | F14: =IF(C14=D14,"Match","Not Match") -> Match | G14: =IF(E14=T14,"Match","Not Match") -> Match | H14: Southern | I14: 3 | J14: PG-CPM | K14: Central | L14: 303 | M14: PG0303 | N14: KAIRUKU/HIRI | P14: FALSE | Q14: Active | R14: HF | S14: 3 | T14: 1854 | U14: =T14*20% -> 370.8 | V14: 499 | W14: 434 | X14: =T14*3% -> 55.62 | Y14: =U14-X14 -> 315.18
A15: 99 | B15: 30403 | C15: Hula SC | D15: Hula SC | E15: 18131 | F15: =IF(C15=D15,"Match","Not Match") -> Match | G15: =IF(E15=T15,"Match","Not Match") -> Match | H15: Southern | I15: 3 | J15: PG-CPM | K15: Central | L15: 304 | M15: PG0304 | N15: RIGO | O15: United Church | P15: TRUE | Q15: Active | R15: HF | S15: 3 | T15: 18131 | U15: =T15*20% -> 3626.2 | V15: 399 | W15: 380 | X15: =T15*3% -> 543.93 | Y15: =U15-X15 -> 3082.27
A16: 84 | B16: 30307 | C16: Inawaia SC | D16: Inawaia SC | E16: 8677 | F16: =IF(C16=D16,"Match","Not Match") -> Match | G16: =IF(E16=T16,"Match","Not Match") -> Match | H16: Southern | I16: 3 | J16: PG-CPM | K16: Central | L16: 303 | M16: PG0303 | N16: KAIRUKU/HIRI | O16: Catholic | P16: TRUE | Q16: Active | R16: HF | S16: 3 | T16: 8677 | U16: =T16*20% -> 1735.4 | V16: 345 | W16: 328 | X16: =T16*3% -> 260.31 | Y16: =U16-X16 -> 1475.09
A17: 66 | B17: 30102 | C17: Iruna HC | D17: Iruna HC | E17: 15376 | F17: =IF(C17=D17,"Match","Not Match") -> Match | G17: =IF(E17=T17,"Match","Not Match") -> Match | H17: Southern | I17: 3 | J17: PG-CPM | K17: Central | L17: 301 | M17: PG0301 | N17: ABAU | O17: United Church | P17: TRUE | Q17: Active | R17: HF | S17: 3 | T17: 15376 | U17: =T17*20% -> 3075.2 | V17: 629 | W17: 599 | X17: =T17*3% -> 461.28 | Y17: =U17-X17 -> 2613.92
A18: 100 | B18: 30404 | C18: Kak SC | D18: Kak SC | E18: 5845 | F18: =IF(C18=D18,"Match","Not Match") -> Match | G18: =IF(E18=T18,"Match","Not Match") -> Match | H18: Southern | I18: 3 | J18: PG-CPM | K18: Central | L18: 304 | M18: PG0304 | N18: RIGO | P18: FALSE | Q18: Active | R18: HF | S18: 3 | T18: 5845 | U18: =T18*20% -> 1169 | V18: 1388 | W18: 1222 | X18: =T18*3% -> 175.35 | Y18: =U18-X18 -> 993.65
A19: 817 | B19: 30321 | C19: Kanosia SC | D19: Kanosia SC | E19: 2066 | F19: =IF(C19=D19,"Match","Not Match") -> Match | G19: =IF(E19=T19,"Match","Not Match") -> Match | H19: Southern | I19: 3 | J19: PG-CPM | K19: Central | L19: 303 | M19: PG0303 | N19: KAIRUKU/HIRI | O19: Catholic | P19: TRUE | Q19: Active | R19: HF | S19: 3 | T19: 2066 | U19: =T19*20% -> 413.2 | V19: 349 | W19: 368 | X19: =T19*3% -> 61.98 | Y19: =U19-X19 -> 351.22
A20: 103 | B20: 30407 | C20: Kokorogoro SC | D20: Kokorogoro SC | E20: 2887 | F20: =IF(C20=D20,"Match","Not Match") -> Match | G20: =IF(E20=T20,"Match","Not Match") -> Match | H20: Southern | I20: 3 | J20: PG-CPM | K20: Central | L20: 304 | M20: PG0304 | N20: RIGO | O20: Salvation Army | P20: TRUE | Q20: Active | R20: HF | S20: 3 | T20: 2887 | U20: =T20*20% -> 577.4 | V20: 192 | W20: 184 | X20: =T20*3% -> 86.61 | Y20: =U20-X20 -> 490.79
A21: 816 | B21: 30320 | C21: Kubuna SC | D21: Kubuna SC | E21: 2571 | F21: =IF(C21=D21,"Match","Not Match") -> Match | G21: =IF(E21=T21,"Match","Not Match") -> Match | H21: Southern | I21: 3 | J21: PG-CPM | K21: Central | L21: 303 | M21: PG0303 | N21: KAIRUKU/HIRI | O21: Catholic | P21: TRUE | Q21: Active | R21: HF | S21: 3 | T21: 2571 | U21: =T21*20% -> 514.2 | V21: 117 | W21: 107 | X21: =T21*3% -> 77.13 | Y21: =U21-X21 -> 437.07
A22: 67 | B22: 30103 | C22: Kupiano HC | D22: Kupiano HC | E22: 20332 | F22: =IF(C22=D22,"Match","Not Match") -> Match | G22: =IF(E22=T22,"Match","Not Match") -> Match | H22: Southern | I22: 3 | J22: PG-CPM | K22: Central | L22: 301 | M22: PG0301 | N22: ABAU | P22: FALSE | Q22: Active | R22: HF | S22: 3 | T22: 20332 | U22: =T22*20% -> 4066.4 | V22: 438 | W22: 400 | X22: =T22*3% -> 609.96 | Y22: =U22-X22 -> 3456.44
A23: 93 | B23: 30316 | C23: Kuriva SC | D23: Kuriva SC | E23: 7124 | F23: =IF(C23=D23,"Match","Not Match") -> Match | G23: =IF(E23=T23,"Match","Not Match") -> Match | H23: Southern | I23: 3 | J23: PG-CPM | K23: Central | L23: 303 | M23: PG0303 | N23: KAIRUKU/HIRI | P23: FALSE | Q23: Active | R23: HF | S23: 3 | T23: 7124 | U23: =T23*20% -> 1424.8 | V23: 131 | W23: 119 | X23: =T23*3% -> 213.72 | Y23: =U23-X23 -> 1211.08
A24: 101 | B24: 30405 | C24: Kwikila HC | D24: Kwikila HC | E24: 39570 | F24: =IF(C24=D24,"Match","Not Match") -> Match | G24: =IF(E24=T24,"Match","Not Match") -> Match | H24: Southern | I24: 3 | J24: PG-CPM | K24: Central | L24: 304 | M24: PG0304 | N24: RIGO | P24: FALSE | Q24: Active | R24: HO | S24: 3 | T24: 39570 | U24: =T24*20% -> 7914 | V24: 308 | W24: 282 | X24: =T24*3% -> 1187.1 | Y24: =U24-X24 -> 6726.9
A25: 94 | B25: 30317 | C25: Laloki Hospital | D25: Laloki Hospital | E25: 4257 | F25: =IF(C25=D25,"Match","Not Match") -> Match | G25: =IF(E25=T25,"Match","Not Match") -> Match | H25: Southern | I25: 3 | J25: PG-CPM | K25: Central | L25: 303 | M25: PG0303 | N25: KAIRUKU/HIRI | P25: FALSE | Q25: Active | R25: HO | S25: 3 | T25: 4257 | U25: =T25*20% -> 851.4 | V25: 810 | W25: 740 | X25: =T25*3% -> 127.71 | Y25: =U25-X25 -> 723.69
A26: 818 | B26: 30322 | C26: Manari SC | D26: Manari SC | E26: 1365 | F26: =IF(C26=D26,"Match","Not Match") -> Match | G26: =IF(E26=T26,"Match","Not Match") -> Match | H26: Southern | I26: 3 | J26: PG-CPM | K26: Central | L26: 303 | M26: PG0303 | N26: KAIRUKU/HIRI | O26: Seventh-Day Adventist | P26: TRUE | Q26: Active | R26: HF | S26: 3 | T26: 1365 | U26: =T26*20% -> 273 | V26: 177 | W26: 139 | X26: =T26*3% -> 40.95 | Y26: =U26-X26 -> 232.05
A27: 68 | B27: 30104 | C27: Moreguina HC | D27: Moreguina HC | E27: 14064 | F27: =IF(C27=D27,"Match","Not Match") -> Match | G27: =IF(E27=T27,"Match","Not Match") -> Match | H27: Southern | I27: 3 | J27: PG-CPM | K27: Central | L27: 301 | M27: PG0301 | N27: ABAU | P27: FALSE | Q27: Active | R27: HF | S27: 3 | T27: 14064 | U27: =T27*20% -> 2812.8 | V27: 556 | W27: 447 | X27: =T27*3% -> 421.92 | Y27: =U27-X27 -> 2390.88
A28: 72 | B28: 30203 | C28: Ononge SC | D28: Ononge SC | E28: 8111 | F28: =IF(C28=D28,"Match","Not Match") -> Match | G28: =IF(E28=T28,"Match","Not Match") -> Match | H28: Southern | I28: 3 | J28: PG-CPM | K28: Central | L28: 302 | M28: PG0302 | N28: GOILALA | O28: Catholic | P28: TRUE | Q28: Active | R28: HF | S28: 3 | T28: 8111 | U28: =T28*20% -> 1622.2 | V28: 441 | W28: 407 | X28: =T28*3% -> 243.33 | Y28: =U28-X28 -> 1378.87
A29: 96 | B29: 30319 | C29: Papa SC | D29: Papa SC | E29: 6958 | F29: =IF(C29=D29,"Match","Not Match") -> Match | G29: =IF(E29=T29,"Match","Not Match") -> Match | H29: Southern | I29: 3 | J29: PG-CPM | K29: Central | L29: 303 | M29: PG0303 | N29: KAIRUKU/HIRI | O29: Salvation Army | P29: TRUE | Q29: Active | R29: HF | S29: 3 | T29: 6958 | U29: =T29*20% -> 1391.6 | V29: 343 | W29: 317 | X29: =T29*3% -> 208.74 | Y29: =U29-X29 -> 1182.86
A30: 11344 | B30: 30106 | C30: Paramana SC | D30: Paramana SC | E30: 15150 | F30: =IF(C30=D30,"Match","Not Match") -> Match | G30: =IF(E30=T30,"Match","Not Match") -> Match | H30: Southern | I30: 3 | J30: PG-CPM | K30: Central | L30: 301 | M30: PG0301 | N30: ABAU | P30: FALSE | Q30: Active | R30: HF | S30: 3 | T30: 15150 | U30: =T30*20% -> 3030 | V30: 47 | W30: 43 | X30: =T30*3% -> 454.5 | Y30: =U30-X30 -> 2575.5
A31: 92 | B31: 30315 | C31: Pau SC | D31: Pau SC | E31: 4337 | F31: =IF(C31=D31,"Match","Not Match") -> Match | G31: =IF(E31=T31,"Match","Not Match") -> Match | H31: Southern | I31: 3 | J31: PG-CPM | K31: Central | L31: 303 | M31: PG0303 | N31: KAIRUKU/HIRI | O31: Seventh-Day Adventist | P31: TRUE | Q31: Active | R31: HF | S31: 3 | T31: 4337 | U31: =T31*20% -> 867.4 | V31: 725 | W31: 669 | X31: =T31*3% -> 130.11 | Y31: =U31-X31 -> 737.29
A32: 91 | B32: 30314 | C32: Porebada SC | D32: Porebada SC | E32: 16945 | F32: =IF(C32=D32,"Match","Not Match") -> Match | G32: =IF(E32=T32,"Match","Not Match") -> Match | H32: Southern | I32: 3 | J32: PG-CPM | K32: Central | L32: 303 | M32: PG0303 | N32: KAIRUKU/HIRI | P32: FALSE | Q32: Active | R32: HF | S32: 3 | T32: 16945 | U32: =T32*20% -> 3389 | V32: 64 | W32: 59 | X32: =T32*3% -> 508.35 | Y32: =U32-X32 -> 2880.65
A33: 85 | B33: 30308 | C33: RMC UC | D33: RMC UC | E33: 18130 | F33: =IF(C33=D33,"Match","Not Match") -> Match | G33: =IF(E33=T33,"Match","Not Match") -> Match | H33: Southern | I33: 3 | J33: PG-CPM | K33: Central | L33: 303 | M33: PG0303 | N33: KAIRUKU/HIRI | P33: FALSE | Q33: Active | R33: HF | S33: 3 | T33: 18130 | U33: =T33*20% -> 3626 | V33: 145 | W33: 121 | X33: =T33*3% -> 543.9 | Y33: =U33-X33 -> 3082.1
A34: 86 | B34: 30309 | C34: Sogeri SC | D34: Sogeri SC | E34: 10882 | F34: =IF(C34=D34,"Match","Not Match") -> Match | G34: =IF(E34=T34,"Match","Not Match") -> Match | H34: Southern | I34: 3 | J34: PG-CPM | K34: Central | L34: 303 | M34: PG0303 | N34: KAIRUKU/HIRI | P34: FALSE | Q34: Active | R34: HF | S34: 3 | T34: 10882 | U34: =T34*20% -> 2176.4 | X34: =T34*3% -> 326.46 | Y34: =U34-X34 -> 1849.94
A35: 73 | B35: 30204 | C35: Tapini HC | D35: Tapini HC | E35: 18149 | F35: =IF(C35=D35,"Match","Not Match") -> Match | G35: =IF(E35=T35,"Match","Not Match") -> Match | H35: Southern | I35: 3 | J35: PG-CPM | K35: Central | L35: 302 | M35: PG0302 | N35: GOILALA | O35: Catholic | P35: TRUE | Q35: Active | R35: HF | S35: 3 | T35: 18149 | U35: =T35*20% -> 3629.8 | X35: =T35*3% -> 544.47 | Y35: =U35-X35 -> 3085.33
A36: 76 | B36: 30207 | C36: Tororo SC | D36: Tororo SC | E36: 3895 | F36: =IF(C36=D36,"Match","Not Match") -> Match | G36: =IF(E36=T36,"Match","Not Match") -> Match | H36: Southern | I36: 3 | J36: PG-CPM | K36: Central | L36: 302 | M36: PG0302 | N36: GOILALA | O36: Seventh-Day Adventist | P36: TRUE | Q36: Active | R36: HF | S36: 3 | T36: 3895 | U36: =T36*20% -> 779 | V36: 67 | W36: 62 | X36: =T36*3% -> 116.85 | Y36: =U36-X36 -> 662.15
A37: 95 | B37: 30318 | C37: Tubusereia SC | D37: Tubusereia SC | E37: 7031 | F37: =IF(C37=D37,"Match","Not Match") -> Match | G37: =IF(E37=T37,"Match","Not Match") -> Match | H37: Southern | I37: 3 | J37: PG-CPM | K37: Central | L37: 303 | M37: PG0303 | N37: KAIRUKU/HIRI | P37: FALSE | Q37: Active | R37: HF | S37: 3 | T37: 7031 | U37: =T37*20% -> 1406.2 | V37: 442 | W37: 411 | X37: =T37*3% -> 210.93 | Y37: =U37-X37 -> 1195.27
A38: 69 | B38: 30105 | C38: Upulima SC | D38: Upulima SC | E38: 3311 | F38: =IF(C38=D38,"Match","Not Match") -> Match | G38: =IF(E38=T38,"Match","Not Match") -> Match | H38: Southern | I38: 3 | J38: PG-CPM | K38: Central | L38: 301 | M38: PG0301 | N38: ABAU | P38: FALSE | Q38: Active | R38: HF | S38: 3 | T38: 3311 | U38: =T38*20% -> 662.2 | V38: 541 | W38: 531 | X38: =T38*3% -> 99.33 | Y38: =U38-X38 -> 562.87
A39: 87 | B39: 30310 | C39: Veifa'a HC | D39: Veifa'a HC | E39: 13693 | F39: =IF(C39=D39,"Match","Not Match") -> Match | G39: =IF(E39=T39,"Match","Not Match") -> Match | H39: Southern | I39: 3 | J39: PG-CPM | K39: Central | L39: 303 | M39: PG0303 | N39: KAIRUKU/HIRI | O39: Catholic | P39: TRUE | Q39: Active | R39: HF | S39: 3 | T39: 13693 | U39: =T39*20% -> 2738.6 | V39: 664 | W39: 578 | X39: =T39*3% -> 410.79 | Y39: =U39-X39 -> 2327.81
A40: 88 | B40: 30311 | C40: Waima SC | D40: Waima SC | E40: 3993 | F40: =IF(C40=D40,"Match","Not Match") -> Match | G40: =IF(E40=T40,"Match","Not Match") -> Match | H40: Southern | I40: 3 | J40: PG-CPM | K40: Central | L40: 303 | M40: PG0303 | N40: KAIRUKU/HIRI | O40: Catholic | P40: TRUE | Q40: Active | R40: HF | S40: 3 | T40: 3993 | U40: =T40*20% -> 798.6 | V40: 747 | W40: 683 | X40: =T40*3% -> 119.79 | Y40: =U40-X40 -> 678.81
...

Sheet Feedbacks
C1: Feedbacks
A2: No | B2: Dashboard name | C2: Area of focus | D2: Type of action (new item or update existing item) | E2: Description or suggetions | F2: Ona comment | G2: Client review (pending/Completed
A3: 1 | B3: MNTE daily summary report | C3: Vaccination campaign health facility report | D3: new item | E3: Add campaign days/ mop up days in filter | F3: Added to the dashboard | G3: completed
A4: 2 | B4: MNTE daily summary report | C4: Vaccination campaign health facility report | D4: new item | E4: Can we add a table for HFs below district number? Understood graph is not possible for HFs (table with Td1,Td2,Td3- target and number achieved (but there is another report of coverage in the coverage report page)
A5: 3 | B5: MNTE daily summary report | C5: Vaccine coverage report | D5: update existing item | E5: filter- round - will it show all three rounds in filter? | F5: Yes this will show depending on the captured data | G5: completed
A6: 4 | B6: MNTE daily summary report | C6: Td vaccination coverage summary | D6: update existing item | E6: (take out total vaccinated and % vaccinated towards target- We don’t count total mixing all the vaccination) | G6: please update the status
A7: 5 | B7: MNTE daily summary report | C7: Td vaccination coverage summary | D7: new item | E7: add Summary table- no disgrégation by prégnance /non pregnancy (refer to picture summary table)- refer to fig on the right | F7: Added the table for Coverage by Vaccine | G7: completed. Please double check the formula: can you please share the formula used at the backend ( the denominiator must be the targerted number of girls and women (both pregrant and non-pregnant)
A8: 6 | B8: Vaccination coveraage | C8: Td vaccination coverage summary | D8: new item | E8: Add round coverage (per round) – in summary- Calculation of coverage following an SIA . Target s the 15-44 yrs (not disaggregation here)- refer to fig on the right | F8: Added the table for Coverage by Round | G8: competed
A9: 7 | B9: Vaccination coveraage | C9: Coverage at provincal level | D9: update existing item | E9: Overall, does not mean – aggregation of all. It should be Td1, Td2, Td3 – replace the graph the same as pregnant , non-pregnant. there should be data label below the graph; | F9: Fixed | G9: completed
A10: 8 | B10: Vaccination coveraage | C10: Coverage at district level | D10: update existing item | E10: same as above | F10: Fixed | G10: completed
A11: 9 | B11: Vaccination coveraage | C11: coverage at health facility level | D11: update existing item | E11: please replace coverage - Td1, Td2, Td3 covearage | F11: Added the Td1, Td2, and Td3 as coverage | G11: completed
A12: 10 | B12: Vaccination coveraage | C12: coverage at provincal level, district level , hf level | D12: update existing item | E12: please check the barchart label- it is showing 482%(refer to figure on the right) | F12: This is dummy data, so expected | G12: noted
A13: 11 | B13: Vaccination coveraage | C13: coverage at national level | D13: update existing item | E13: add the breakdown of coverage by Pregannat and non-pregant (like in Province and district) - no need of graph or chart as it is % national levle | F13: Not sure if this is needed, each geographical level has a chart for the same | G13: thanks we need to see at the national level as well. kindly add for national level
A14: 12 | B14: MNTE daily summary report | C14: Vaccination campaign Health Facility Daily Summary Report | D14: update existing item | E14: add the filter for mopping up as the data collection tool has two categories - campaign days and mopup dayus | F14: This filter already exists | G14: agree. completed
A15: 13 | B15: MNTE daily summary report | C15: Mopping up vaccination | D15: new item | E15: mop-up coverage for each round) and by province, district and health facility; total women (with category of pregnant women and non-pregnant) | F15: Replied via email | G15: If there are 2 or more missed women in the RCM response, ( two no response from this question” Did the woman receive a Td vaccine during the SIA?), we will take as required for Mop-up.please find the example below; refer to MR campaign dashbaord too. ( please record by round)
A16: 14 | B16: MNTE daily summary report | C16: Mopping up vacciation HF (raw data) | D16: new item (refer to MR campaign dashboard) | E16: raw data for extraction (similar to MR campaign superset dashboard) | F16: Replied via email | G16: please find the example below; refer to MR campaign dashbaord too.
A17: 15 | B17: MNTE daily summary report | C17: Reach- the bar chart | D17: update existing item | E17: bar chart- pregnant and non-pregnant dsiplay - to simply Embed the proportion % inside the bar chart ( instedad of % at the legend) | F17: Updated. | G17: completed
A18: 16 | B18: =B17 -> MNTE daily summary report | C18: Provincial, disrrict coverage bar chart | D18: update existing item | E18: display all provinces, districts in each province in legend by default- regardless of the data input (zero or none) - differnt display for zero and none data | F18: Replied via email | G18: we agree not to display non-reporting level in the garpah but keep or list all the provinces/distirct in the tablet so that we know which is reporting and which is not reporting
A19: 17 | B19: =B18 -> MNTE daily summary report | C19: all display charts and tables | D19: update existing item | E19: the filter of mop-up days and campaign days are not working for the summary table; if you filter mop-up days the number is the same as the campaign days. please check and update the dashboard data formula in relation to the filter of mop-up days and campaing days | G19: completed
A20: 18 | B20: RCM (List of villages of eligible women who did not receive Td vaccines) | D20: new item | E20: add List of villages of eligible women who did not receive Td vaccines ( from the House to House RCM); the current table is only from the transit point | G20: completred
A21: 19 | B21: summary table of coverage report | C21: data discrepancy | D21: update existing item | E21: Jiwaka provincial target from the provided table (sheet 2 of this excel) is 75671 whereas the dashboard target show 70,841. please check the data query for JIwaka, plesae see the two screenshorts for comparison
A22: 20 | B22: RCM | C22: provinces visited by different organization is blank wehre are there are data in the other forms | D22: update existing item | E22: provinces visited by different organization is blank wehre are there are data in the other forms
B26: Mop-up vaccination summary | C26: If there are 2 or more missed women in the RCM response, ( two no response from this question” Did the woman receive a Td vaccine during the SIA?), we will take as required for Mop-up.

Sheet targets
A1: id | B1: hf_code | C1: hf_name | F1: HF Match | G1: Pop Match | H1: Region | I1: province_code | J1: province_iso_code | K1: province | L1: district_code | M1: district_iso_code | N1: district | O1: churchtype | P1: is_church | Q1: status | R1: hf_type | S1: province_id | T1: total_pop | U1: pop_15_44_yrs | V1: pop_less_then_1_yr | W1: estimated_births | X1: preg_target | Y1: non_preg_target
A2: 78 | B2: 30301 | C2: Agevairu SC | D2: Agevairu SC | E2: 10532 | F2: =IF(C2=D2,"Match","Not Match") -> Match | G2: =IF(E2=T2,"Match","Not Match") -> Match | H2: Southern | I2: 3 | J2: PG-CPM | K2: Central | L2: 303 | M2: PG0303 | N2: KAIRUKU/HIRI | P2: FALSE | Q2: Active | R2: HF | S2: 3 | T2: 10532 | U2: =T2*20% -> 2106.4 | V2: 269 | W2: 207 | X2: =T2*3% -> 315.96 | Y2: =U2-X2 -> 1790.44
A3: 79 | B3: 30302 | C3: Akufa SC | D3: Akufa SC | E3: 6227 | F3: =IF(C3=D3,"Match","Not Match") -> Match | G3: =IF(E3=T3,"Match","Not Match") -> Match | H3: Southern | I3: 3 | J3: PG-CPM | K3: Central | L3: 303 | M3: PG0303 | N3: KAIRUKU/HIRI | O3: Catholic | P3: TRUE | Q3: Active | R3: HF | S3: 3 | T3: 6227 | U3: =T3*20% -> 1245.4 | V3: 169 | W3: 130 | X3: =T3*3% -> 186.81 | Y3: =U3-X3 -> 1058.59
A4: 80 | B4: 30303 | C4: Bakoiudu SC | D4: Bakoiudu SC | E4: 3690 | F4: =IF(C4=D4,"Match","Not Match") -> Match | G4: =IF(E4=T4,"Match","Not Match") -> Match | H4: Southern | I4: 3 | J4: PG-CPM | K4: Central | L4: 303 | M4: PG0303 | N4: KAIRUKU/HIRI | O4: Catholic | P4: TRUE | Q4: Active | R4: HF | S4: 3 | T4: 3690 | U4: =T4*20% -> 738 | V4: 104 | W4: 80 | X4: =T4*3% -> 110.7 | Y4: =U4-X4 -> 627.3
A5: 11392 | B5: 30107 | C5: Bam CHP | D5: Bam CHP | E5: 5038 | F5: =IF(C5=D5,"Match","Not Match") -> Match | G5: =IF(E5=T5,"Match","Not Match") -> Match | H5: Southern | I5: 3 | J5: PG-CPM | K5: Central | L5: 301 | M5: PG0301 | N5: ABAU | P5: FALSE | Q5: Active | R5: HF | S5: 3 | T5: 5038 | U5: =T5*20% -> 1007.6 | V5: 547 | W5: 418 | X5: =T5*3% -> 151.14 | Y5: =U5-X5 -> 856.46
A6: 81 | B6: 30304 | C6: Bereina HC | D6: Bereina HC | E6: 14298 | F6: =IF(C6=D6,"Match","Not Match") -> Match | G6: =IF(E6=T6,"Match","Not Match") -> Match | H6: Southern | I6: 3 | J6: PG-CPM | K6: Central | L6: 303 | M6: PG0303 | N6: KAIRUKU/HIRI | P6: FALSE | Q6: Active | R6: HF | S6: 3 | T6: 14298 | U6: =T6*20% -> 2859.6 | V6: 345 | W6: 312 | X6: =T6*3% -> 428.94 | Y6: =U6-X6 -> 2430.66
A7: 97 | B7: 30401 | C7: Boku SC | D7: Boku SC | E7: 3726 | F7: =IF(C7=D7,"Match","Not Match") -> Match | G7: =IF(E7=T7,"Match","Not Match") -> Match | H7: Southern | I7: 3 | J7: PG-CPM | K7: Central | L7: 304 | M7: PG0304 | N7: RIGO | P7: FALSE | Q7: Active | R7: HF | S7: 3 | T7: 3726 | U7: =T7*20% -> 745.2 | V7: 278 | W7: 252 | X7: =T7*3% -> 111.78 | Y7: =U7-X7 -> 633.42
A8: 102 | B8: 30406 | C8: Boregaina SC | D8: Boregaina SC | E8: 4954 | F8: =IF(C8=D8,"Match","Not Match") -> Match | G8: =IF(E8=T8,"Match","Not Match") -> Match | H8: Southern | I8: 3 | J8: PG-CPM | K8: Central | L8: 304 | M8: PG0304 | N8: RIGO | O8: Salvation Army | P8: TRUE | Q8: Active | R8: HF | S8: 3 | T8: 4954 | U8: =T8*20% -> 990.8 | V8: 228 | W8: 207 | X8: =T8*3% -> 148.62 | Y8: =U8-X8 -> 842.18
A9: 65 | B9: 30101 | C9: Boru HC | D9: Boru HC | E9: 1997 | F9: =IF(C9=D9,"Match","Not Match") -> Match | G9: =IF(E9=T9,"Match","Not Match") -> Match | H9: Southern | I9: 3 | J9: PG-CPM | K9: Central | L9: 301 | M9: PG0301 | N9: ABAU | O9: United Church | P9: TRUE | Q9: Active | R9: HF | S9: 3 | T9: 1997 | U9: =T9*20% -> 399.4 | V9: 136 | W9: 123 | X9: =T9*3% -> 59.91 | Y9: =U9-X9 -> 339.49
A10: 90 | B10: 30313 | C10: Doa SC | D10: Doa SC | E10: 4111 | F10: =IF(C10=D10,"Match","Not Match") -> Match | G10: =IF(E10=T10,"Match","Not Match") -> Match | H10: Southern | I10: 3 | J10: PG-CPM | K10: Central | L10: 303 | M10: PG0303 | N10: KAIRUKU/HIRI | P10: FALSE | Q10: Active | R10: HF | S10: 3 | T10: 4111 | U10: =T10*20% -> 822.2 | V10: 342 | W10: 315 | X10: =T10*3% -> 123.33 | Y10: =U10-X10 -> 698.87
A11: 98 | B11: 30402 | C11: Dorobisoro SC | D11: Dorobisoro SC | E11: 2310 | F11: =IF(C11=D11,"Match","Not Match") -> Match | G11: =IF(E11=T11,"Match","Not Match") -> Match | H11: Southern | I11: 3 | J11: PG-CPM | K11: Central | L11: 304 | M11: PG0304 | N11: RIGO | P11: FALSE | Q11: Active | R11: HF | S11: 3 | T11: 2310 | U11: =T11*20% -> 462 | V11: 243 | W11: 224 | X11: =T11*3% -> 69.3 | Y11: =U11-X11 -> 392.7
A12: 82 | B12: 30305 | C12: Efogi SC | D12: Efogi SC | E12: 1202 | F12: =IF(C12=D12,"Match","Not Match") -> Match | G12: =IF(E12=T12,"Match","Not Match") -> Match | H12: Southern | I12: 3 | J12: PG-CPM | K12: Central | L12: 303 | M12: PG0303 | N12: KAIRUKU/HIRI | O12: Seventh-Day Adventist | P12: TRUE | Q12: Active | R12: HF | S12: 3 | T12: 1202 | U12: =T12*20% -> 240.4 | V12: 210 | W12: 193 | X12: =T12*3% -> 36.06 | Y12: =U12-X12 -> 204.34
A13: 70 | B13: 30201 | C13: Fane SC | D13: Fane SC | E13: 10766 | F13: =IF(C13=D13,"Match","Not Match") -> Match | G13: =IF(E13=T13,"Match","Not Match") -> Match | H13: Southern | I13: 3 | J13: PG-CPM | K13: Central | L13: 302 | M13: PG0302 | N13: GOILALA | O13: Catholic | P13: TRUE | Q13: Active | R13: HF | S13: 3 | T13: 10766 | U13: =T13*20% -> 2153.2 | V13: 1478 | W13: 1181 | X13: =T13*3% -> 322.98 | Y13: =U13-X13 -> 1830.22
A14: 83 | B14: 30306 | C14: Goldie SC | D14: Goldie SC | E14: 1854 | F14: =IF(C14=D14,"Match","Not Match") -> Match | G14: =IF(E14=T14,"Match","Not Match") -> Match | H14: Southern | I14: 3 | J14: PG-CPM | K14: Central | L14: 303 | M14: PG0303 | N14: KAIRUKU/HIRI | P14: FALSE | Q14: Active | R14: HF | S14: 3 | T14: 1854 | U14: =T14*20% -> 370.8 | V14: 499 | W14: 434 | X14: =T14*3% -> 55.62 | Y14: =U14-X14 -> 315.18
A15: 99 | B15: 30403 | C15: Hula SC | D15: Hula SC | E15: 18131 | F15: =IF(C15=D15,"Match","Not Match") -> Match | G15: =IF(E15=T15,"Match","Not Match") -> Match | H15: Southern | I15: 3 | J15: PG-CPM | K15: Central | L15: 304 | M15: PG0304 | N15: RIGO | O15: United Church | P15: TRUE | Q15: Active | R15: HF | S15: 3 | T15: 18131 | U15: =T15*20% -> 3626.2 | V15: 399 | W15: 380 | X15: =T15*3% -> 543.93 | Y15: =U15-X15 -> 3082.27
A16: 84 | B16: 30307 | C16: Inawaia SC | D16: Inawaia SC | E16: 8677 | F16: =IF(C16=D16,"Match","Not Match") -> Match | G16: =IF(E16=T16,"Match","Not Match") -> Match | H16: Southern | I16: 3 | J16: PG-CPM | K16: Central | L16: 303 | M16: PG0303 | N16: KAIRUKU/HIRI | O16: Catholic | P16: TRUE | Q16: Active | R16: HF | S16: 3 | T16: 8677 | U16: =T16*20% -> 1735.4 | V16: 345 | W16: 328 | X16: =T16*3% -> 260.31 | Y16: =U16-X16 -> 1475.09
A17: 66 | B17: 30102 | C17: Iruna HC | D17: Iruna HC | E17: 15376 | F17: =IF(C17=D17,"Match","Not Match") -> Match | G17: =IF(E17=T17,"Match","Not Match") -> Match | H17: Southern | I17: 3 | J17: PG-CPM | K17: Central | L17: 301 | M17: PG0301 | N17: ABAU | O17: United Church | P17: TRUE | Q17: Active | R17: HF | S17: 3 | T17: 15376 | U17: =T17*20% -> 3075.2 | V17: 629 | W17: 599 | X17: =T17*3% -> 461.28 | Y17: =U17-X17 -> 2613.92
A18: 100 | B18: 30404 | C18: Kak SC | D18: Kak SC | E18: 5845 | F18: =IF(C18=D18,"Match","Not Match") -> Match | G18: =IF(E18=T18,"Match","Not Match") -> Match | H18: Southern | I18: 3 | J18: PG-CPM | K18: Central | L18: 304 | M18: PG0304 | N18: RIGO | P18: FALSE | Q18: Active | R18: HF | S18: 3 | T18: 5845 | U18: =T18*20% -> 1169 | V18: 1388 | W18: 1222 | X18: =T18*3% -> 175.35 | Y18: =U18-X18 -> 993.65
A19: 817 | B19: 30321 | C19: Kanosia SC | D19: Kanosia SC | E19: 2066 | F19: =IF(C19=D19,"Match","Not Match") -> Match | G19: =IF(E19=T19,"Match","Not Match") -> Match | H19: Southern | I19: 3 | J19: PG-CPM | K19: Central | L19: 303 | M19: PG0303 | N19: KAIRUKU/HIRI | O19: Catholic | P19: TRUE | Q19: Active | R19: HF | S19: 3 | T19: 2066 | U19: =T19*20% -> 413.2 | V19: 349 | W19: 368 | X19: =T19*3% -> 61.98 | Y19: =U19-X19 -> 351.22
A20: 103 | B20: 30407 | C20: Kokorogoro SC | D20: Kokorogoro SC | E20: 2887 | F20: =IF(C20=D20,"Match","Not Match") -> Match | G20: =IF(E20=T20,"Match","Not Match") -> Match | H20: Southern | I20: 3 | J20: PG-CPM | K20: Central | L20: 304 | M20: PG0304 | N20: RIGO | O20: Salvation Army | P20: TRUE | Q20: Active | R20: HF | S20: 3 | T20: 2887 | U20: =T20*20% -> 577.4 | V20: 192 | W20: 184 | X20: =T20*3% -> 86.61 | Y20: =U20-X20 -> 490.79
A21: 816 | B21: 30320 | C21: Kubuna SC | D21: Kubuna SC | E21: 2571 | F21: =IF(C21=D21,"Match","Not Match") -> Match | G21: =IF(E21=T21,"Match","Not Match") -> Match | H21: Southern | I21: 3 | J21: PG-CPM | K21: Central | L21: 303 | M21: PG0303 | N21: KAIRUKU/HIRI | O21: Catholic | P21: TRUE | Q21: Active | R21: HF | S21: 3 | T21: 2571 | U21: =T21*20% -> 514.2 | V21: 117 | W21: 107 | X21: =T21*3% -> 77.13 | Y21: =U21-X21 -> 437.07
A22: 67 | B22: 30103 | C22: Kupiano HC | D22: Kupiano HC | E22: 20332 | F22: =IF(C22=D22,"Match","Not Match") -> Match | G22: =IF(E22=T22,"Match","Not Match") -> Match | H22: Southern | I22: 3 | J22: PG-CPM | K22: Central | L22: 301 | M22: PG0301 | N22: ABAU | P22: FALSE | Q22: Active | R22: HF | S22: 3 | T22: 20332 | U22: =T22*20% -> 4066.4 | V22: 438 | W22: 400 | X22: =T22*3% -> 609.96 | Y22: =U22-X22 -> 3456.44
A23: 93 | B23: 30316 | C23: Kuriva SC | D23: Kuriva SC | E23: 7124 | F23: =IF(C23=D23,"Match","Not Match") -> Match | G23: =IF(E23=T23,"Match","Not Match") -> Match | H23: Southern | I23: 3 | J23: PG-CPM | K23: Central | L23: 303 | M23: PG0303 | N23: KAIRUKU/HIRI | P23: FALSE | Q23: Active | R23: HF | S23: 3 | T23: 7124 | U23: =T23*20% -> 1424.8 | V23: 131 | W23: 119 | X23: =T23*3% -> 213.72 | Y23: =U23-X23 -> 1211.08
A24: 101 | B24: 30405 | C24: Kwikila HC | D24: Kwikila HC | E24: 39570 | F24: =IF(C24=D24,"Match","Not Match") -> Match | G24: =IF(E24=T24,"Match","Not Match") -> Match | H24: Southern | I24: 3 | J24: PG-CPM | K24: Central | L24: 304 | M24: PG0304 | N24: RIGO | P24: FALSE | Q24: Active | R24: HO | S24: 3 | T24: 39570 | U24: =T24*20% -> 7914 | V24: 308 | W24: 282 | X24: =T24*3% -> 1187.1 | Y24: =U24-X24 -> 6726.9
A25: 94 | B25: 30317 | C25: Laloki Hospital | D25: Laloki Hospital | E25: 4257 | F25: =IF(C25=D25,"Match","Not Match") -> Match | G25: =IF(E25=T25,"Match","Not Match") -> Match | H25: Southern | I25: 3 | J25: PG-CPM | K25: Central | L25: 303 | M25: PG0303 | N25: KAIRUKU/HIRI | P25: FALSE | Q25: Active | R25: HO | S25: 3 | T25: 4257 | U25: =T25*20% -> 851.4 | V25: 810 | W25: 740 | X25: =T25*3% -> 127.71 | Y25: =U25-X25 -> 723.69
A26: 818 | B26: 30322 | C26: Manari SC | D26: Manari SC | E26: 1365 | F26: =IF(C26=D26,"Match","Not Match") -> Match | G26: =IF(E26=T26,"Match","Not Match") -> Match | H26: Southern | I26: 3 | J26: PG-CPM | K26: Central | L26: 303 | M26: PG0303 | N26: KAIRUKU/HIRI | O26: Seventh-Day Adventist | P26: TRUE | Q26: Active | R26: HF | S26: 3 | T26: 1365 | U26: =T26*20% -> 273 | V26: 177 | W26: 139 | X26: =T26*3% -> 40.95 | Y26: =U26-X26 -> 232.05
A27: 68 | B27: 30104 | C27: Moreguina HC | D27: Moreguina HC | E27: 14064 | F27: =IF(C27=D27,"Match","Not Match") -> Match | G27: =IF(E27=T27,"Match","Not Match") -> Match | H27: Southern | I27: 3 | J27: PG-CPM | K27: Central | L27: 301 | M27: PG0301 | N27: ABAU | P27: FALSE | Q27: Active | R27: HF | S27: 3 | T27: 14064 | U27: =T27*20% -> 2812.8 | V27: 556 | W27: 447 | X27: =T27*3% -> 421.92 | Y27: =U27-X27 -> 2390.88
A28: 72 | B28: 30203 | C28: Ononge SC | D28: Ononge SC | E28: 8111 | F28: =IF(C28=D28,"Match","Not Match") -> Match | G28: =IF(E28=T28,"Match","Not Match") -> Match | H28: Southern | I28: 3 | J28: PG-CPM | K28: Central | L28: 302 | M28: PG0302 | N28: GOILALA | O28: Catholic | P28: TRUE | Q28: Active | R28: HF | S28: 3 | T28: 8111 | U28: =T28*20% -> 1622.2 | V28: 441 | W28: 407 | X28: =T28*3% -> 243.33 | Y28: =U28-X28 -> 1378.87
A29: 96 | B29: 30319 | C29: Papa SC | D29: Papa SC | E29: 6958 | F29: =IF(C29=D29,"Match","Not Match") -> Match | G29: =IF(E29=T29,"Match","Not Match") -> Match | H29: Southern | I29: 3 | J29: PG-CPM | K29: Central | L29: 303 | M29: PG0303 | N29: KAIRUKU/HIRI | O29: Salvation Army | P29: TRUE | Q29: Active | R29: HF | S29: 3 | T29: 6958 | U29: =T29*20% -> 1391.6 | V29: 343 | W29: 317 | X29: =T29*3% -> 208.74 | Y29: =U29-X29 -> 1182.86
A30: 11344 | B30: 30106 | C30: Paramana SC | D30: Paramana SC | E30: 15150 | F30: =IF(C30=D30,"Match","Not Match") -> Match | G30: =IF(E30=T30,"Match","Not Match") -> Match | H30: Southern | I30: 3 | J30: PG-CPM | K30: Central | L30: 301 | M30: PG0301 | N30: ABAU | P30: FALSE | Q30: Active | R30: HF | S30: 3 | T30: 15150 | U30: =T30*20% -> 3030 | V30: 47 | W30: 43 | X30: =T30*3% -> 454.5 | Y30: =U30-X30 -> 2575.5
A31: 92 | B31: 30315 | C31: Pau SC | D31: Pau SC | E31: 4337 | F31: =IF(C31=D31,"Match","Not Match") -> Match | G31: =IF(E31=T31,"Match","Not Match") -> Match | H31: Southern | I31: 3 | J31: PG-CPM | K31: Central | L31: 303 | M31: PG0303 | N31: KAIRUKU/HIRI | O31: Seventh-Day Adventist | P31: TRUE | Q31: Active | R31: HF | S31: 3 | T31: 4337 | U31: =T31*20% -> 867.4 | V31: 725 | W31: 669 | X31: =T31*3% -> 130.11 | Y31: =U31-X31 -> 737.29
A32: 91 | B32: 30314 | C32: Porebada SC | D32: Porebada SC | E32: 16945 | F32: =IF(C32=D32,"Match","Not Match") -> Match | G32: =IF(E32=T32,"Match","Not Match") -> Match | H32: Southern | I32: 3 | J32: PG-CPM | K32: Central | L32: 303 | M32: PG0303 | N32: KAIRUKU/HIRI | P32: FALSE | Q32: Active | R32: HF | S32: 3 | T32: 16945 | U32: =T32*20% -> 3389 | V32: 64 | W32: 59 | X32: =T32*3% -> 508.35 | Y32: =U32-X32 -> 2880.65
A33: 85 | B33: 30308 | C33: RMC UC | D33: RMC UC | E33: 18130 | F33: =IF(C33=D33,"Match","Not Match") -> Match | G33: =IF(E33=T33,"Match","Not Match") -> Match | H33: Southern | I33: 3 | J33: PG-CPM | K33: Central | L33: 303 | M33: PG0303 | N33: KAIRUKU/HIRI | P33: FALSE | Q33: Active | R33: HF | S33: 3 | T33: 18130 | U33: =T33*20% -> 3626 | V33: 145 | W33: 121 | X33: =T33*3% -> 543.9 | Y33: =U33-X33 -> 3082.1
A34: 86 | B34: 30309 | C34: Sogeri SC | D34: Sogeri SC | E34: 10882 | F34: =IF(C34=D34,"Match","Not Match") -> Match | G34: =IF(E34=T34,"Match","Not Match") -> Match | H34: Southern | I34: 3 | J34: PG-CPM | K34: Central | L34: 303 | M34: PG0303 | N34: KAIRUKU/HIRI | P34: FALSE | Q34: Active | R34: HF | S34: 3 | T34: 10882 | U34: =T34*20% -> 2176.4 | X34: =T34*3% -> 326.46 | Y34: =U34-X34 -> 1849.94
A35: 73 | B35: 30204 | C35: Tapini HC | D35: Tapini HC | E35: 18149 | F35: =IF(C35=D35,"Match","Not Match") -> Match | G35: =IF(E35=T35,"Match","Not Match") -> Match | H35: Southern | I35: 3 | J35: PG-CPM | K35: Central | L35: 302 | M35: PG0302 | N35: GOILALA | O35: Catholic | P35: TRUE | Q35: Active | R35: HF | S35: 3 | T35: 18149 | U35: =T35*20% -> 3629.8 | X35: =T35*3% -> 544.47 | Y35: =U35-X35 -> 3085.33
A36: 76 | B36: 30207 | C36: Tororo SC | D36: Tororo SC | E36: 3895 | F36: =IF(C36=D36,"Match","Not Match") -> Match | G36: =IF(E36=T36,"Match","Not Match") -> Match | H36: Southern | I36: 3 | J36: PG-CPM | K36: Central | L36: 302 | M36: PG0302 | N36: GOILALA | O36: Seventh-Day Adventist | P36: TRUE | Q36: Active | R36: HF | S36: 3 | T36: 3895 | U36: =T36*20% -> 779 | V36: 67 | W36: 62 | X36: =T36*3% -> 116.85 | Y36: =U36-X36 -> 662.15
A37: 95 | B37: 30318 | C37: Tubusereia SC | D37: Tubusereia SC | E37: 7031 | F37: =IF(C37=D37,"Match","Not Match") -> Match | G37: =IF(E37=T37,"Match","Not Match") -> Match | H37: Southern | I37: 3 | J37: PG-CPM | K37: Central | L37: 303 | M37: PG0303 | N37: KAIRUKU/HIRI | P37: FALSE | Q37: Active | R37: HF | S37: 3 | T37: 7031 | U37: =T37*20% -> 1406.2 | V37: 442 | W37: 411 | X37: =T37*3% -> 210.93 | Y37: =U37-X37 -> 1195.27
A38: 69 | B38: 30105 | C38: Upulima SC | D38: Upulima SC | E38: 3311 | F38: =IF(C38=D38,"Match","Not Match") -> Match | G38: =IF(E38=T38,"Match","Not Match") -> Match | H38: Southern | I38: 3 | J38: PG-CPM | K38: Central | L38: 301 | M38: PG0301 | N38: ABAU | P38: FALSE | Q38: Active | R38: HF | S38: 3 | T38: 3311 | U38: =T38*20% -> 662.2 | V38: 541 | W38: 531 | X38: =T38*3% -> 99.33 | Y38: =U38-X38 -> 562.87
A39: 87 | B39: 30310 | C39: Veifa'a HC | D39: Veifa'a HC | E39: 13693 | F39: =IF(C39=D39,"Match","Not Match") -> Match | G39: =IF(E39=T39,"Match","Not Match") -> Match | H39: Southern | I39: 3 | J39: PG-CPM | K39: Central | L39: 303 | M39: PG0303 | N39: KAIRUKU/HIRI | O39: Catholic | P39: TRUE | Q39: Active | R39: HF | S39: 3 | T39: 13693 | U39: =T39*20% -> 2738.6 | V39: 664 | W39: 578 | X39: =T39*3% -> 410.79 | Y39: =U39-X39 -> 2327.81
A40: 88 | B40: 30311 | C40: Waima SC | D40: Waima SC | E40: 3993 | F40: =IF(C40=D40,"Match","Not Match") -> Match | G40: =IF(E40=T40,"Match","Not Match") -> Match | H40: Southern | I40: 3 | J40: PG-CPM | K40: Central | L40: 303 | M40: PG0303 | N40: KAIRUKU/HIRI | O40: Catholic | P40: TRUE | Q40: Active | R40: HF | S40: 3 | T40: 3993 | U40: =T40*20% -> 798.6 | V40: 747 | W40: 683 | X40: =T40*3% -> 119.79 | Y40: =U40-X40 -> 678.81
...

Sheet old_targets
A1: id | B1: hf_code | C1: hf_name | D1: Region | E1: province_code | F1: province_iso_code | G1: province | H1: district_code | I1: district_iso_code | J1: district | K1: churchtype | L1: is_church | M1: status | N1: hf_type | O1: province_id | P1: total_pop | Q1: pop_15_44_yrs | R1: pop_less_then_1_yr | S1: estimated_births | T1: preg_target | U1: non_preg_target
A2: 785 | B2: 40104 | C2: 6 Mile UC | D2: Southern | E2: 4 | F2: {=INDEX(Sheet1!$F$2:$F$876,MATCH($E2,Sheet1!$E$2:$E$7876,0))} -> PG-NCD | G2: National Capital District | H2: 401 | I2: {=INDEX(Sheet1!$I$2:$I$876,MATCH(TRIM($H2),TRIM(Sheet1!$H$2:$H$880),0))} -> 0 | J2: MORESBY NORTH EAST | L2: FALSE | M2: Active | N2: HF | O2: 4 | P2: 16119 | Q2: =P2*20% -> 3223.8 | R2: 609 | S2: 467 | T2: =P2*3% -> 483.57 | U2: =Q2-T2 -> 2740.23
A3: 786 | B3: 40105 | C3: 9 Mile UC | D3: Southern | E3: 4 | F3: {=INDEX(Sheet1!$F$2:$F$876,MATCH($E3,Sheet1!$E$2:$E$7876,0))} -> PG-NCD | G3: National Capital District | H3: 401 | I3: {=INDEX(Sheet1!$I$2:$I$876,MATCH(TRIM($H3),TRIM(Sheet1!$H$2:$H$880),0))} -> 0 | J3: MORESBY NORTH EAST | K3: Hope World Wide (PNG) | L3: TRUE | M3: Active | N3: HF | O3: 4 | P3: 11601 | Q3: =P3*20% -> 2320.2 | R3: 438 | S3: 336 | T3: =P3*3% -> 348.03 | U3: =Q3-T3 -> 1972.17
A4: 12 | B4: 10112 | C4: Adiba SC | D4: Southern | E4: 1 | F4: {=INDEX(Sheet1!$F$2:$F$876,MATCH($E4,Sheet1!$E$2:$E$7876,0))} -> PG-WHM | G4: Western | H4: 101 | I4: {=INDEX(Sheet1!$I$2:$I$876,MATCH(TRIM($H4),TRIM(Sheet1!$H$2:$H$880),0))} -> PG0101 | J4: MIDDLE FLY | K4: Evangelical Church of PNG (ECPNG) | L4: TRUE | M4: Active | N4: HF | O4: 1 | P4: 11914 | Q4: =P4*20% -> 2382.8 | R4: 450 | S4: 346 | T4: =P4*3% -> 357.42 | U4: =Q4-T4 -> 2025.38
A5: 166 | B5: 60101 | C5: Afore HC | D5: Southern | E5: 6 | F5: {=INDEX(Sheet1!$F$2:$F$876,MATCH($E5,Sheet1!$E$2:$E$7876,0))} -> PG-NPP | G5: Northern | H5: 601 | I5: {=INDEX(Sheet1!$I$2:$I$876,MATCH(TRIM($H5),TRIM(Sheet1!$H$2:$H$880),0))} -> PG0601 | J5: IJIVITARI | L5: FALSE | M5: Active | N5: HF | O5: 6 | P5: 4942 | Q5: =P5*20% -> 988.4 | R5: 187 | S5: 143 | T5: =P5*3% -> 148.26 | U5: =Q5-T5 -> 840.14
A6: 125 | B6: 50101 | C6: Agaun SC | D6: Southern | E6: 5 | F6: {=INDEX(Sheet1!$F$2:$F$876,MATCH($E6,Sheet1!$E$2:$E$7876,0))} -> PG-MBA | G6: Milne Bay | H6: 501 | I6: {=INDEX(Sheet1!$I$2:$I$876,MATCH(TRIM($H6),TRIM(Sheet1!$H$2:$H$880),0))} -> PG0501 | J6: ALOTAU | K6: Anglican | L6: TRUE | M6: Active | N6: HF | O6: 5 | P6: 10465 | Q6: =P6*20% -> 2093 | R6: 395 | S6: 303 | T6: =P6*3% -> 313.95 | U6: =Q6-T6 -> 1779.05
A7: 78 | B7: 30301 | C7: Agevairu SC | D7: Southern | E7: 3 | F7: {=INDEX(Sheet1!$F$2:$F$876,MATCH($E7,Sheet1!$E$2:$E$7876,0))} -> PG-CPM | G7: Central | H7: 303 | I7: {=INDEX(Sheet1!$I$2:$I$876,MATCH(TRIM($H7),TRIM(Sheet1!$H$2:$H$880),0))} -> PG0303 | J7: KAIRUKU/HIRI | L7: FALSE | M7: Active | N7: HF | O7: 3 | P7: 7136 | Q7: =P7*20% -> 1427.2 | R7: 269 | S7: 207 | T7: =P7*3% -> 214.08 | U7: =Q7-T7 -> 1213.12
A8: 449 | B8: 130301 | C8: Aiome HC | D8: Momase | E8: 13 | F8: {=INDEX(Sheet1!$F$2:$F$876,MATCH($E8,Sheet1!$E$2:$E$7876,0))} -> PG-MPM | G8: Madang | H8: 1303 | I8: {=INDEX(Sheet1!$I$2:$I$876,MATCH(TRIM($H8),TRIM(Sheet1!$H$2:$H$880),0))} -> PG1303 | J8: MIDDLE RAMU | L8: FALSE | M8: Active | N8: HF | O8: 13 | P8: 5357 | Q8: =P8*20% -> 1071.4 | R8: 202 | S8: 155 | T8: =P8*3% -> 160.71 | U8: =Q8-T8 -> 910.69
A9: 525 | B9: 150101 | C9: Aitape/Raihu SC | D9: Momase | E9: 15 | F9: {=INDEX(Sheet1!$F$2:$F$876,MATCH($E9,Sheet1!$E$2:$E$7876,0))} -> PG-SAN | G9: West Sepik | H9: 1501 | I9: {=INDEX(Sheet1!$I$2:$I$876,MATCH(TRIM($H9),TRIM(Sheet1!$H$2:$H$880),0))} -> PG1501 | J9: AITAPE/LUMI | K9: Catholic | L9: TRUE | M9: Active | N9: HO | O9: 15 | P9: 15375 | Q9: =P9*20% -> 3075 | R9: 581 | S9: 446 | T9: =P9*3% -> 461.25 | U9: =Q9-T9 -> 2613.75
A10: 860 | B10: 70719 | C10: Aiyo CHP | D10: Highlands | E10: 7 | F10: {=INDEX(Sheet1!$F$2:$F$876,MATCH($E10,Sheet1!$E$2:$E$7876,0))} -> PG-SHM | G10: Southern Highlands | H10: 707 | I10: {=INDEX(Sheet1!$I$2:$I$876,MATCH(TRIM($H10),TRIM(Sheet1!$H$2:$H$880),0))} -> PG0707 | J10: NIPA/KUTUBU | L10: FALSE | M10: Active | N10: HF | O10: 7 | P10: 6333 | Q10: =P10*20% -> 1266.6 | R10: 239 | S10: 184 | T10: =P10*3% -> 189.99 | U10: =Q10-T10 -> 1076.61
A11: 244 | B11: 80208 | C11: Aiyokos SC | D11: Highlands | E11: 8 | F11: {=INDEX(Sheet1!$F$2:$F$876,MATCH($E11,Sheet1!$E$2:$E$7876,0))} -> PG-EPW | G11: Enga | H11: 802 | I11: {=INDEX(Sheet1!$I$2:$I$876,MATCH(TRIM($H11),TRIM(Sheet1!$H$2:$H$880),0))} -> PG0802 | J11: KOMPIAM | K11: Baptist | L11: TRUE | M11: Active | N11: HF | O11: 8 | P11: 6246 | Q11: =P11*20% -> 1249.2 | R11: 236 | S11: 181 | T11: =P11*3% -> 187.38 | U11: =Q11-T11 -> 1061.82
A12: 641 | B12: 190101 | C12: Aka HC | D12: Islands | E12: 19 | F12: {=INDEX(Sheet1!$F$2:$F$876,MATCH($E12,Sheet1!$E$2:$E$7876,0))} -> PG-WBK | G12: West New Britain | H12: 1901 | I12: {=INDEX(Sheet1!$I$2:$I$876,MATCH(TRIM($H12),TRIM(Sheet1!$H$2:$H$880),0))} -> PG1901 | J12: KANDRIAN/GLOUCESTER | L12: FALSE | M12: Active | N12: HF | O12: 19 | P12: 3130 | Q12: =P12*20% -> 626 | R12: 118 | S12: 91 | T12: =P12*3% -> 93.9 | U12: =Q12-T12 -> 532.1
A13: 167 | B13: 60102 | C13: Ako SC | D13: Southern | E13: 6 | F13: {=INDEX(Sheet1!$F$2:$F$876,MATCH($E13,Sheet1!$E$2:$E$7876,0))} -> PG-NPP | G13: Northern | H13: 601 | I13: {=INDEX(Sheet1!$I$2:$I$876,MATCH(TRIM($H13),TRIM(Sheet1!$H$2:$H$880),0))} -> PG0601 | J13: IJIVITARI | L13: FALSE | M13: Active | N13: HF | O13: 6 | P13: 5342 | Q13: =P13*20% -> 1068.4 | R13: 202 | S13: 155 | T13: =P13*3% -> 160.26 | U13: =Q13-T13 -> 908.14
A14: 845 | B14: 190116 | C14: Akonga CHP | D14: Islands | E14: 19 | F14: {=INDEX(Sheet1!$F$2:$F$876,MATCH($E14,Sheet1!$E$2:$E$7876,0))} -> PG-WBK | G14: West New Britain | H14: 1901 | I14: {=INDEX(Sheet1!$I$2:$I$876,MATCH(TRIM($H14),TRIM(Sheet1!$H$2:$H$880),0))} -> PG1901 | J14: KANDRIAN/GLOUCESTER | L14: FALSE | M14: Active | N14: HF | O14: 19 | P14: 2799 | Q14: =P14*20% -> 559.8 | R14: 106 | S14: 81 | T14: =P14*3% -> 83.97 | U14: =Q14-T14 -> 475.83
A15: 79 | B15: 30302 | C15: Akufa SC | D15: Southern | E15: 3 | F15: {=INDEX(Sheet1!$F$2:$F$876,MATCH($E15,Sheet1!$E$2:$E$7876,0))} -> PG-CPM | G15: Central | H15: 303 | I15: {=INDEX(Sheet1!$I$2:$I$876,MATCH(TRIM($H15),TRIM(Sheet1!$H$2:$H$880),0))} -> PG0303 | J15: KAIRUKU/HIRI | K15: Catholic | L15: TRUE | M15: Active | N15: HF | O15: 3 | P15: 4482 | Q15: =P15*20% -> 896.4 | R15: 169 | S15: 130 | T15: =P15*3% -> 134.46 | U15: =Q15-T15 -> 761.94
A16: 503 | B16: 140306 | C16: Albinama SC | D16: Momase | E16: 14 | F16: {=INDEX(Sheet1!$F$2:$F$876,MATCH($E16,Sheet1!$E$2:$E$7876,0))} -> PG-ESW | G16: East Sepik | H16: 1403 | I16: {=INDEX(Sheet1!$I$2:$I$876,MATCH(TRIM($H16),TRIM(Sheet1!$H$2:$H$880),0))} -> PG1403 | J16: MAPRIK | K16: South Sea Evangelical Church (SSEC) | L16: TRUE | M16: Active | N16: HF | O16: 14 | P16: 8797 | Q16: =P16*20% -> 1759.4 | R16: 332 | S16: 255 | T16: =P16*3% -> 263.91 | U16: =Q16-T16 -> 1495.49
A17: 440 | B17: 130201 | C17: Alexishaven HC | D17: Momase | E17: 13 | F17: {=INDEX(Sheet1!$F$2:$F$876,MATCH($E17,Sheet1!$E$2:$E$7876,0))} -> PG-MPM | G17: Madang | H17: 1302 | I17: {=INDEX(Sheet1!$I$2:$I$876,MATCH(TRIM($H17),TRIM(Sheet1!$H$2:$H$880),0))} -> PG1302 | J17: MADANG | K17: Catholic | L17: TRUE | M17: Active | N17: HF | O17: 13 | P17: 815 | Q17: =P17*20% -> 163 | R17: 31 | S17: 24 | T17: =P17*3% -> 24.45 | U17: =Q17-T17 -> 138.55
A18: 299 | B18: 90703 | C18: Alkena SC | D18: Highlands | E18: 9 | F18: {=INDEX(Sheet1!$F$2:$F$876,MATCH($E18,Sheet1!$E$2:$E$7876,0))} -> PG-WPD | G18: Western Highlands | H18: 907 | I18: {=INDEX(Sheet1!$I$2:$I$876,MATCH(TRIM($H18),TRIM(Sheet1!$H$2:$H$880),0))} -> PG0907 | J18: TAMBUL/NEBILYER | L18: FALSE | M18: Active | N18: HF | O18: 9 | P18: 402 | Q18: =P18*20% -> 80.4 | R18: 15 | S18: 12 | T18: =P18*3% -> 12.06 | U18: =Q18-T18 -> 68.34
A19: 126 | B19: 50102 | C19: Alotau HO | D19: Southern | E19: 5 | F19: {=INDEX(Sheet1!$F$2:$F$876,MATCH($E19,Sheet1!$E$2:$E$7876,0))} -> PG-MBA | G19: Milne Bay | H19: 501 | I19: {=INDEX(Sheet1!$I$2:$I$876,MATCH(TRIM($H19),TRIM(Sheet1!$H$2:$H$880),0))} -> PG0501 | J19: ALOTAU | L19: FALSE | M19: Active | N19: HO | O19: 5 | P19: 5079 | Q19: =P19*20% -> 1015.8 | R19: 192 | S19: 147 | T19: =P19*3% -> 152.37 | U19: =Q19-T19 -> 863.43
A20: 127 | B20: 50103 | C20: Alotau UC | D20: Southern | E20: 5 | F20: {=INDEX(Sheet1!$F$2:$F$876,MATCH($E20,Sheet1!$E$2:$E$7876,0))} -> PG-MBA | G20: Milne Bay | H20: 501 | I20: {=INDEX(Sheet1!$I$2:$I$876,MATCH(TRIM($H20),TRIM(Sheet1!$H$2:$H$880),0))} -> PG0501 | J20: ALOTAU | L20: FALSE | M20: Active | N20: HF | O20: 5 | P20: 8189 | Q20: =P20*20% -> 1637.8 | R20: 309 | S20: 237 | T20: =P20*3% -> 245.67 | U20: =Q20-T20 -> 1392.13
A21: 872 | B21: 210517 | C21: Aluni CHP | D21: Highlands | E21: 21 | F21: {=INDEX(Sheet1!$F$2:$F$876,MATCH($E21,Sheet1!$E$2:$E$7876,0))} -> PG-HLA* | G21: Hela | H21: 2105 | I21: {=INDEX(Sheet1!$I$2:$I$876,MATCH(TRIM($H21),TRIM(Sheet1!$H$2:$H$880),0))} -> PG2105 | J21: KOROBA/KOPIAGO | K21: Christian Apostolic Fellowship (CAF) | L21: TRUE | M21: Active | N21: HF | O21: 21 | P21: 17652 | Q21: =P21*20% -> 3530.4 | R21: 667 | S21: 512 | T21: =P21*3% -> 529.56 | U21: =Q21-T21 -> 3000.84
A22: 550 | B22: 150401 | C22: Amanab HC | D22: Momase | E22: 15 | F22: {=INDEX(Sheet1!$F$2:$F$876,MATCH($E22,Sheet1!$E$2:$E$7876,0))} -> PG-SAN | G22: West Sepik | H22: 1504 | I22: {=INDEX(Sheet1!$I$2:$I$876,MATCH(TRIM($H22),TRIM(Sheet1!$H$2:$H$880),0))} -> PG1504 | J22: VANIMO/GREEN RIVER | L22: FALSE | M22: Active | N22: HF | O22: 15 | P22: 20333 | Q22: =P22*20% -> 4066.6 | R22: 768 | S22: 590 | T22: =P22*3% -> 609.99 | U22: =Q22-T22 -> 3456.61
A23: 168 | B23: 60103 | C23: Ambasi SC | D23: Southern | E23: 6 | F23: {=INDEX(Sheet1!$F$2:$F$876,MATCH($E23,Sheet1!$E$2:$E$7876,0))} -> PG-NPP | G23: Northern | H23: 601 | I23: {=INDEX(Sheet1!$I$2:$I$876,MATCH(TRIM($H23),TRIM(Sheet1!$H$2:$H$880),0))} -> PG0601 | J23: IJIVITARI | L23: FALSE | M23: Active | N23: HF | O23: 6 | P23: 2116 | Q23: =P23*20% -> 423.2 | R23: 80 | S23: 61 | T23: =P23*3% -> 63.48 | U23: =Q23-T23 -> 359.72
A24: 489 | B24: 140201 | C24: Amboin SC | D24: Momase | E24: 14 | F24: {=INDEX(Sheet1!$F$2:$F$876,MATCH($E24,Sheet1!$E$2:$E$7876,0))} -> PG-ESW | G24: East Sepik | H24: 1402 | I24: {=INDEX(Sheet1!$I$2:$I$876,MATCH(TRIM($H24),TRIM(Sheet1!$H$2:$H$880),0))} -> PG1402 | J24: ANGORAM | L24: FALSE | M24: Active | N24: HF | O24: 14 | P24: 9664 | Q24: =P24*20% -> 1932.8 | R24: 365 | S24: 280 | T24: =P24*3% -> 289.92 | U24: =Q24-T24 -> 1642.88
A25: 752 | B25: 220408 | C25: Ambullua SC | D25: Highlands | E25: 22 | F25: {=INDEX(Sheet1!$F$2:$F$876,MATCH($E25,Sheet1!$E$2:$E$7876,0))} -> PG-JWK* | G25: Jiwaka | H25: 2204 | I25: {=INDEX(Sheet1!$I$2:$I$876,MATCH(TRIM($H25),TRIM(Sheet1!$H$2:$H$880),0))} -> PG2204 | J25: JIMI | K25: Catholic | L25: TRUE | M25: Active | N25: HF | O25: 22 | P25: 15896 | Q25: =P25*20% -> 3179.2 | R25: 600 | S25: 461 | T25: =P25*3% -> 476.88 | U25: =Q25-T25 -> 2702.32
A26: 480 | B26: 140101 | C26: Ambunti HC | D26: Momase | E26: 14 | F26: {=INDEX(Sheet1!$F$2:$F$876,MATCH($E26,Sheet1!$E$2:$E$7876,0))} -> PG-ESW | G26: East Sepik | H26: 1401 | I26: {=INDEX(Sheet1!$I$2:$I$876,MATCH(TRIM($H26),TRIM(Sheet1!$H$2:$H$880),0))} -> PG1401 | J26: AMBUNTI/DREKIKIR | L26: FALSE | M26: Active | N26: HF | O26: 14 | P26: 9055 | Q26: =P26*20% -> 1811 | R26: 342 | S26: 263 | T26: =P26*3% -> 271.65 | U26: =Q26-T26 -> 1539.35
A27: 642 | B27: 190102 | C27: Amio SC | D27: Islands | E27: 19 | F27: {=INDEX(Sheet1!$F$2:$F$876,MATCH($E27,Sheet1!$E$2:$E$7876,0))} -> PG-WBK | G27: West New Britain | H27: 1901 | I27: {=INDEX(Sheet1!$I$2:$I$876,MATCH(TRIM($H27),TRIM(Sheet1!$H$2:$H$880),0))} -> PG1901 | J27: KANDRIAN/GLOUCESTER | L27: FALSE | M27: Active | N27: HF | O27: 19 | P27: 33248 | Q27: =P27*20% -> 6649.6 | R27: 1255 | S27: 964 | T27: =P27*3% -> 997.44 | U27: =Q27-T27 -> 5652.16
A28: 361 | B28: 110601 | C28: Andakombi SC | D28: Highlands | E28: 11 | F28: {=INDEX(Sheet1!$F$2:$F$876,MATCH($E28,Sheet1!$E$2:$E$7876,0))} -> PG-EHG | G28: Eastern Highlands | H28: 1106 | I28: {=INDEX(Sheet1!$I$2:$I$876,MATCH(TRIM($H28),TRIM(Sheet1!$H$2:$H$880),0))} -> PG1106 | J28: OBURA/WONENARA | L28: FALSE | M28: Active | N28: HF | O28: 11 | P28: 19014 | Q28: =P28*20% -> 3802.8 | R28: 718 | S28: 551 | T28: =P28*3% -> 570.42 | U28: =Q28-T28 -> 3232.38
A29: 243 | B29: 80207 | C29: Anditale SC | D29: Highlands | E29: 8 | F29: {=INDEX(Sheet1!$F$2:$F$876,MATCH($E29,Sheet1!$E$2:$E$7876,0))} -> PG-EPW | G29: Enga | H29: 802 | I29: {=INDEX(Sheet1!$I$2:$I$876,MATCH(TRIM($H29),TRIM(Sheet1!$H$2:$H$880),0))} -> PG0802 | J29: KOMPIAM | L29: FALSE | M29: Active | N29: HF | O29: 8 | P29: 3935 | Q29: =P29*20% -> 787 | R29: 149 | S29: 114 | T29: =P29*3% -> 118.05 | U29: =Q29-T29 -> 668.95
A30: 402 | B30: 120502 | C30: Angau Hospital | D30: Momase | E30: 12 | F30: {=INDEX(Sheet1!$F$2:$F$876,MATCH($E30,Sheet1!$E$2:$E$7876,0))} -> PG-MPL | G30: Morobe | H30: 1205 | I30: {=INDEX(Sheet1!$I$2:$I$876,MATCH(TRIM($H30),TRIM(Sheet1!$H$2:$H$880),0))} -> PG1205 | J30: LAE | L30: FALSE | M30: Active | N30: HO | O30: 12 | P30: 2065 | Q30: =P30*20% -> 413 | R30: 78 | S30: 60 | T30: =P30*3% -> 61.95 | U30: =Q30-T30 -> 351.05
A31: 824 | B31: 120501 | C31: Angau Hospital UC | D31: Momase | E31: 12 | F31: {=INDEX(Sheet1!$F$2:$F$876,MATCH($E31,Sheet1!$E$2:$E$7876,0))} -> PG-MPL | G31: Morobe | H31: 1205 | I31: {=INDEX(Sheet1!$I$2:$I$876,MATCH(TRIM($H31),TRIM(Sheet1!$H$2:$H$880),0))} -> PG1205 | J31: LAE | L31: FALSE | M31: Inactive | N31: HF | O31: 12 | P31: 27065 | Q31: =P31*20% -> 5413 | R31: 1022 | S31: 785 | T31: =P31*3% -> 811.95 | U31: =Q31-T31 -> 4601.05
A32: 11341 | B32: 40210 | C32: Anglicare Begabari | D32: Southern | E32: 4 | F32: {=INDEX(Sheet1!$F$2:$F$876,MATCH($E32,Sheet1!$E$2:$E$7876,0))} -> PG-NCD | G32: National Capital District | H32: 402 | I32: {=INDEX(Sheet1!$I$2:$I$876,MATCH(TRIM($H32),TRIM(Sheet1!$H$2:$H$880),0))} -> 0 | J32: MORESBY NORTH WEST | K32: Anglican | L32: TRUE | M32: Active | N32: HF | O32: 4 | P32: 9943 | Q32: =P32*20% -> 1988.6 | R32: 375 | S32: 288 | T32: =P32*3% -> 298.29 | U32: =Q32-T32 -> 1690.31
A33: 490 | B33: 140202 | C33: Angoram HC | D33: Momase | E33: 14 | F33: {=INDEX(Sheet1!$F$2:$F$876,MATCH($E33,Sheet1!$E$2:$E$7876,0))} -> PG-ESW | G33: East Sepik | H33: 1402 | I33: {=INDEX(Sheet1!$I$2:$I$876,MATCH(TRIM($H33),TRIM(Sheet1!$H$2:$H$880),0))} -> PG1402 | J33: ANGORAM | L33: FALSE | M33: Active | N33: HF | O33: 14 | P33: 2996 | Q33: =P33*20% -> 599.2 | R33: 113 | S33: 87 | T33: =P33*3% -> 89.88 | U33: =Q33-T33 -> 509.32
A34: 533 | B34: 150201 | C34: Anguganak HC | D34: Momase | E34: 15 | F34: {=INDEX(Sheet1!$F$2:$F$876,MATCH($E34,Sheet1!$E$2:$E$7876,0))} -> PG-SAN | G34: West Sepik | H34: 1502 | I34: {=INDEX(Sheet1!$I$2:$I$876,MATCH(TRIM($H34),TRIM(Sheet1!$H$2:$H$880),0))} -> PG1502 | J34: NUKU | K34: Christian Brethren Church (CBC) | L34: TRUE | M34: Active | N34: HF | O34: 15 | P34: 6461 | Q34: =P34*20% -> 1292.2 | R34: 244 | S34: 187 | T34: =P34*3% -> 193.83 | U34: =Q34-T34 -> 1098.37
A35: 450 | B35: 130302 | C35: Annaberg HC | D35: Momase | E35: 13 | F35: {=INDEX(Sheet1!$F$2:$F$876,MATCH($E35,Sheet1!$E$2:$E$7876,0))} -> PG-MPM | G35: Madang | H35: 1303 | I35: {=INDEX(Sheet1!$I$2:$I$876,MATCH(TRIM($H35),TRIM(Sheet1!$H$2:$H$880),0))} -> PG1303 | J35: MIDDLE RAMU | K35: Catholic | L35: TRUE | M35: Active | N35: HF | O35: 13 | P35: 7935 | Q35: =P35*20% -> 1587 | R35: 300 | S35: 230 | T35: =P35*3% -> 238.05 | U35: =Q35-T35 -> 1348.95
A36: 624 | B36: 180301 | C36: Aona SC | D36: Islands | E36: 18 | F36: {=INDEX(Sheet1!$F$2:$F$876,MATCH($E36,Sheet1!$E$2:$E$7876,0))} -> PG-EBR | G36: East New Britain | H36: 1803 | I36: {=INDEX(Sheet1!$I$2:$I$876,MATCH(TRIM($H36),TRIM(Sheet1!$H$2:$H$880),0))} -> PG1803 | J36: POMIO | K36: Catholic | L36: TRUE | M36: Active | N36: HF | O36: 18 | P36: 14298 | Q36: =P36*20% -> 2859.6 | R36: 540 | S36: 415 | T36: =P36*3% -> 428.94 | U36: =Q36-T36 -> 2430.66
A37: 486 | B37: 140108 | C37: April River SC | D37: Momase | E37: 14 | F37: {=INDEX(Sheet1!$F$2:$F$876,MATCH($E37,Sheet1!$E$2:$E$7876,0))} -> PG-ESW | G37: East Sepik | H37: 1401 | I37: {=INDEX(Sheet1!$I$2:$I$876,MATCH(TRIM($H37),TRIM(Sheet1!$H$2:$H$880),0))} -> PG1401 | J37: AMBUNTI/DREKIKIR | K37: South Sea Evangelical Church (SSEC) | L37: TRUE | M37: Active | N37: HF | O37: 14 | P37: 6577 | Q37: =P37*20% -> 1315.4 | R37: 248 | S37: 191 | T37: =P37*3% -> 197.31 | U37: =Q37-T37 -> 1118.09
A38: 241 | B38: 80205 | C38: Araguli SC | D38: Highlands | E38: 8 | F38: {=INDEX(Sheet1!$F$2:$F$876,MATCH($E38,Sheet1!$E$2:$E$7876,0))} -> PG-EPW | G38: Enga | H38: 802 | I38: {=INDEX(Sheet1!$I$2:$I$876,MATCH(TRIM($H38),TRIM(Sheet1!$H$2:$H$880),0))} -> PG0802 | J38: KOMPIAM | K38: Baptist | L38: TRUE | M38: Active | N38: HF | O38: 8 | P38: 11094 | Q38: =P38*20% -> 2218.8 | R38: 419 | S38: 322 | T38: =P38*3% -> 332.82 | U38: =Q38-T38 -> 1885.98
A39: 673 | B39: 200101 | C39: Arawa DH | D39: Islands | E39: 20 | F39: {=INDEX(Sheet1!$F$2:$F$876,MATCH($E39,Sheet1!$E$2:$E$7876,0))} -> PG-NSB | G39: Autonomous Region of Bougainville | H39: 2001 | I39: {=INDEX(Sheet1!$I$2:$I$876,MATCH(TRIM($H39),TRIM(Sheet1!$H$2:$H$880),0))} -> PG2002 | J39: CENTRAL BOUGAINVILLE | L39: FALSE | M39: Active | N39: HO | O39: 20 | P39: 11735 | Q39: =P39*20% -> 2347 | R39: 443 | S39: 340 | T39: =P39*3% -> 352.05 | U39: =Q39-T39 -> 1994.95
A40: 432 | B40: 130101 | C40: Ariangon SC | D40: Momase | E40: 13 | F40: {=INDEX(Sheet1!$F$2:$F$876,MATCH($E40,Sheet1!$E$2:$E$7876,0))} -> PG-MPM | G40: Madang | H40: 1301 | I40: {=INDEX(Sheet1!$I$2:$I$876,MATCH(TRIM($H40),TRIM(Sheet1!$H$2:$H$880),0))} -> PG1301 | J40: BOGIA | K40: Catholic | L40: TRUE | M40: Active | N40: HF | O40: 13 | P40: 3239 | Q40: =P40*20% -> 647.8 | R40: 122 | S40: 94 | T40: =P40*3% -> 97.17 | U40: =Q40-T40 -> 550.63
...

Sheet RCM (both HtH and transit)
A1: KPI Name | B1: Definition | C1: Formula | D1: Visualization Type | E1: Data Source | F1: Mockup
A2: Add filter for RCM House to House, RCM tranist points
A3: Summary | B3: Display of the summary : no of visits, # regions visited, # provinces visited, # district visited, # heath facilities visited, type of sessions monitored (by three categories, fixes, mobile, outreach) | C3: Count and categorize the numbers and variables | D3: Table (export csv) | E3: ODK submission | F3: refer to MR campaign dashboard
A4: Map of location visited during RCM | D4: Maps and red dots for locations (export csv) | E4: GPS locations collected from ODK (RCM House to House and transit) | F4: refer to MR campaign dashboard
A5: Provinces visited by differnet organization | B5: Provinces which are visited by different organization types | C5: provinces in column left/ categories of supervisors/monitors on right/ number in the cells) | D5: Tabular form (export csv) | E5: ODK submission at the end of the form (RCM house to house and RCM transit) | F5: refer to MR campaign dashboard
A6: Summary of RCM by province | B6: Columns: Region, province, # villages visited,# transit visited, # women 15-44 years, # eligible women vaccinated, # eligible women NOT vaccinated, # of villlages requiring mop-up | C6: Count and categorize the numbers and variables | D6: Table (export csv) | E6: ODK submission of RCM House to House and Transits | F6: refer to MR campaign dashboard
